Workbook

Sheet Cover Sheet
B9: DataX Data Governance - Metadata
B10: Metadata Quality Calculate Metric Template - Operationalization
B13: Version 02.00.00

Sheet Instruction
B2: Instruction
B3: This file for calculate quality metric which contain 5 tab sheet as Mandatory
B5: No. | C5: Tab sheet | D5: Description
B6: 1 | C6: Scope & Condition by field | D6: Refer to the shortcut guidelines to define conditions for calculating quality metrics.
B7: 2 | C7: Summary | D7: Summarize quality metric results by field.
B8: 3 | C8: Element | D8: Provide a summary of the total elements.
B9: 4 | C9: Cal_Business Metadata | D9: Compute metadata quality metrics in the Business Part.
B10: 5 | C10: Cal_Technical - Data Set | D10: Compute metadata quality metrics in the Technical Dataset part.
B11: 6 | C11: Cal_Technical - Column | D11: Compute metadata quality metrics in the Technical Column section.
B13: For How to setting file calculate template
B14: Refer: | C14: Metadata Quality Metric Manual Setting_V01.00.00

Sheet Technical Column
A1: System/Data Subject Area Name | B1: Schema/Database Name | C1: Data Set Name | D1: Column Name | E1: Data Zone (MDZ/GDZ) | F1: PII/Non-PII | G1: CDE/Non-CDE | H1: Type | I1: Format | J1: Length | K1: Nullable | L1: Updated Date | M1: Updated By | N1: Additional Remarks
A2: Customer Information | B2: scbs_ds | C2: all_customers | D2: card_type | E2: INVX Data Lake | F2: Non-PII | G2: Y | H2: string | I2: Character | J2: - | K2: No | L2: 45300 | M2: Phatcharaporn L. | N2: -
A3: Customer Information | B3: scbs_ds | C3: all_customers | D3: passport_country | E3: INVX Data Lake | F3: Non-PII | G3: Y | H3: string | I3: Character | J3: 2 | K3: Yes | L3: 45300 | M3: Phatcharaporn L. | N3: -
A4: Customer Information | B4: scbs_ds | C4: all_customers | D4: card_number | E4: INVX Data Lake | F4: PII | G4: Y | H4: string | I4: Numeric | J4: 13 | K4: No | L4: 45264 | M4: Tossawat P | N4: -
A5: Customer Information | B5: scbs_ds | C5: all_customers | D5: card_expiry_date | E5: INVX Data Lake | F5: Non-PII | G5: Y | H5: Date | I5: YYYY-MM-DD | J5: - | K5: Yes | L5: 45264 | M5: Tossawat P | N5: -
A6: Customer Information | B6: scbs_ds | C6: all_customers | D6: gender | E6: INVX Data Lake | F6: Non-PII | G6: Y | H6: string | I6: Character | J6: 1 | K6: Yes | L6: 45300 | M6: Phatcharaporn L. | N6: -
A7: Customer Information | B7: scbs_ds | C7: all_customers | D7: birth_date | E7: INVX Data Lake | F7: PII | G7: Y | H7: Date | I7: YYYY-MM-DD | J7: - | K7: Yes | L7: 45264 | M7: Tossawat P | N7: -
A8: Customer Information | B8: scbs_ds | C8: all_customers | D8: nationality | E8: INVX Data Lake | F8: Non-PII | G8: Y | H8: string | I8: Character | J8: 2 | K8: No | L8: 45264 | M8: Tossawat P | N8: -
A9: Customer Information | B9: scbs_ds | C9: all_customers | D9: mobile_number | E9: INVX Data Lake | F9: PII | G9: Y | H9: string | I9: Numeric | J9: 10 | K9: Yes | L9: 45300 | M9: Phatcharaporn L. | N9: -
A10: Customer Information | B10: scbs_ds | C10: all_customers | D10: eq_firsttelno1 | E10: INVX Data Lake | F10: PII | G10: N | H10: string | I10: Numeric | J10: 10 | K10: Yes | L10: 45264 | M10: Tossawat P | N10: -
A11: Customer Information | B11: scbs_ds | C11: all_customers | D11: eq_firsttelno2 | E11: INVX Data Lake | F11: PII | G11: N | H11: string | I11: Numeric | J11: - | K11: Yes | L11: 45264 | M11: Tossawat P | N11: -
A12: Customer Information | B12: scbs_ds | C12: all_customers | D12: eq_secondtelno1 | E12: INVX Data Lake | F12: PII | G12: N | H12: string | I12: Numeric | J12: - | K12: Yes | L12: 45264 | M12: Tossawat P | N12: -
A13: Customer Information | B13: scbs_ds | C13: all_customers | D13: eq_secondtelno2 | E13: INVX Data Lake | F13: PII | G13: N | H13: string | I13: Numeric | J13: - | K13: Yes | L13: 45264 | M13: Tossawat P | N13: -
... A155: fund_transactions | B155: scbs_ds | C155: fund_transactions | D155: owner_ic_license_on_run_date | E155: INVX Data Lake | F155: Non-PII | G155: N | H155: string | I155: - | J155: - | K155: Yes | L155: 45503 | M155: Tossawat P | N155: -

Sheet Technical Data Set
A1: Data Set Name | B1: Data Set Description | C1: Data Set Update Frequency | D1: Updated Date | E1: Updated By | F1: Additional Remarks
A2: all_customers | B2: The table that collects all customer data | C2: Monthly | D2: 45286 | E2: Tossawat P | F2: The data lake update cycle is every end of the month.
A3: all_accounts | B3: It is a table showing the collection of customer account information. Including officials that are taken care of in each product | C3: Monthly | D3: 45324 | E3: Tossawat.P | F3: The data lake update cycle is every end of the month.
A4: scbs_center_cq_cash_balance | B4: N/A | C4: Monthly | D4: 45491 | E4: Tossawat.P | F4: The data lake update cycle is every end of the month.
A5: fund_portfolio | B5: Collect customer fund product information and create individual portfolios. | C5: Monthly | D5: 45503 | E5: Tossawat P
A6: fund_transactions | B6: Mutual fund investment transaction data storage | C6: Monthly | D6: 45503 | E6: Tossawat P

Sheet Business Metadata
A1: No. | B1: Business Attribute Name | C1: Business Definition (EN) | D1: Column Name | E1: PII/Non-PII | F1: CDE/Non-CDE | G1: List of Allowable Values | H1: Sample Data | I1: Business Data Steward | J1: Data Owner | K1: Updated Date | L1: Updated By | M1: Additional Remarks | N1: Subdomain
A2: 1 | B2: Card Type List | C2: Type of card that customers use as evidence for account opening(ประเภทบัตรที่ลูกค้าใช้เป็นหลักฐานในการเปิดบัญชี) Sample list of allowable values include: CITIZEN_CARD = บัตรประชาชน PASSPORT = หนังสือเดินทาง ALIEN_CARD = บัตรต่างด้าว Company Tax ID = หมายเลขประจำตัวผู้เสียภาษีของบริษัท Company No = หมายเลขบริษัท Government_ID = หมายเลขรัฐวิสาหกิจ Please refer to link of allowable values for complete list of allowable values. | D2: card_type | E2: Non-PII | F2: Y | G2: Card_Type | H2: CITIZEN_CARD PASSPORT ALIEN_CARD Company Tax ID Company No | I2: Nattaphat Buddharee | J2: Pichai Lertsupongkit | K2: 45300 | L2: Tossawat P | M2: - | N2: Customer Information
A3: 2 | B3: Passport Country Code | C3: The passport country code represents the name of the country from which the passport was issued (only in the case of PASSPORT). It is stored as a 2-digit or 3-digit abbreviation code ประเทศที่ออก passport ของลูกค้า (เฉพาะกรณี PASSPORT เท่านั้น) Sample list of allowable values include: IN = INDIA CN = CHINA GB = UNITED KINGDOM US = UNITED STATES JP = JAPAN Please refer to link of allowable values for complete list of allowable values. | D3: passport_country | E3: Non-PII | F3: Y | G3: Passport_Country_code | H3: IN CN GB US JP | I3: Nattaphat Buddharee | J3: Pichai Lertsupongkit | K3: 45300 | L3: Tossawat P | M3: - | N3: Customer Information
A4: 3 | B4: Card Number | C4: Identification Number from the card the customer uses to open the account It can be a Thai ID card, passport No, or Alien identification card. This depends on the type of customer. Identification Number จากบัตรที่ลูกค้าใช้เปิดบัญชี | D4: card_number | E4: PII | F4: Y | G4: - | H4: 351274171 TR4395794 Z2666801 1100200285146 1100200459250 | I4: Nattaphat Buddharee | J4: Pichai Lertsupongkit | K4: 45264 | L4: Tossawat P | M4: - | N4: Customer Information
A5: 4 | B5: Card expiry Date | C5: Card expiration date means the date printed on the identification card used by the customer as evidence for opening an account. which indicates the expiration of the card's lifespan This date is set by the card issuing authority. The format should be ""YYYY-MM-DD" record: - If the customer does not have an expiration date on the card, the value will be 9999-12-31. วันหมดอายุของบัตรที่ลูกค้าใช้เป็นหลักฐานในการเปิดบัญชี | D5: card_expiry_date | E5: Non-PII | F5: Y | G5: - | H5: 9999-12-31 2099-12-31 1970-01-01 2023-12-31 2026-12-31 | I5: Nattaphat Buddharee | J5: Pichai Lertsupongkit | K5: 45264 | L5: Tossawat P | M5: - | N5: Customer Information
A6: 5 | B6: Gender Code | C6: Gender Code represents the code used to identify the gender of the customer. Current list of allowable values includes: M = Male F = Female O = Other | D6: gender | E6: Non-PII | F6: Y | G6: - | H6: M F O | I6: Nattaphat Buddharee | J6: Pichai Lertsupongkit | K6: 45300 | L6: Tossawat P | M6: - | N6: Customer Information
A7: 6 | B7: Birth Date | C7: Birthday means the customer's date of birth. The storage format is YYYY-MM-DD. | D7: birth_date | E7: PII | F7: Y | G7: - | H7: 1900-01-01 1996-10-03 1995-01-01 1996-01-01 1995-12-05 | I7: Nattaphat Buddharee | J7: Pichai Lertsupongkit | K7: 45264 | L7: Tossawat P | M7: - | N7: Customer Information
A8: 7 | B8: Nationality Code | C8: Nationality Code represents the nationality code of the customer. It is stored as a 2-digit or 3-digit abbreviation code depending on the system Sample list of allowable values include: TH = THAILAND IN = INDIA CN = CHINA GB = UNITED KINGDOM US = UNITED STATES Please refer to link of allowable values for complete list of allowable values. | D8: nationality | E8: Non-PII | F8: Y | G8: Nationality Code' | H8: TH IN CN GB US | I8: Nattaphat Buddharee | J8: Pichai Lertsupongkit | K8: 45264 | L8: Tossawat P | M8: - | N8: Customer Information
A9: 8 | B9: Mobile Number | C9: Mobile phone number means the customer's phone number used to contact them. The format should be Mobile phone number in Thailand (10 digits): '0XX-XXX-XXXX' (X is an integer from 0 to 9) Home telephone number within Thailand (9 digits): '0X-XXX-XXXX' (X is an integer from 0 to 9) Phone numbers outside Thailand (maximum 15 digits): The format depends on the country but the format should be Country Code + Country Destination Code + Member Number Remark: Other values ​​that are 1 digit or [] or Null must be checked and corrected | D9: mobile_number | E9: PII | F9: Y | G9: - | H9: 0000000000 0 0802221201 [] 0819181971 | I9: Nattaphat Buddharee | J9: Pichai Lertsupongkit | K9: 45300 | L9: Tossawat P | M9: - | N9: Customer Information
A10: 9 | B10: First Equity's First Phone Number | C10: TBC | D10: eq_firsttelno1 | E10: PII | F10: N | G10: - | H10: 0802221201 0894761228 0819181971 0818749586 0891409776 | I10: Nattaphat Buddharee | J10: Pichai Lertsupongkit | K10: 45264 | L10: Tossawat P | M10: - | N10: Customer Information
A11: 10 | B11: First Equity's Second Phone Number | C11: TBC | D11: eq_firsttelno2 | E11: PII | F11: N | G11: - | H11: [] ไม่มี 000000000 0 038685155 | I11: Nattaphat Buddharee | J11: Pichai Lertsupongkit | K11: 45264 | L11: Tossawat P | M11: - | N11: Customer Information
A12: 11 | B12: Second Equity's First Phone Number | C12: TBC | D12: eq_secondtelno1 | E12: PII | F12: N | G12: - | H12: [] 0854881096 0000000000 0899574455 0802221201 | I12: Nattaphat Buddharee | J12: Pichai Lertsupongkit | K12: 45264 | L12: Tossawat P | M12: - | N12: Customer Information
A13: 12 | B13: Second Equity's Second Phone Number | C13: TBC | D13: eq_secondtelno2 | E13: PII | F13: N | G13: - | H13: [] - 026616661 038493561 022608505 | I13: Nattaphat Buddharee | J13: Pichai Lertsupongkit | K13: 45264 | L13: Tossawat P | M13: - | N13: Customer Information
... A68: 67 | B68: Bank Account Pay Number | C68: Account number for pay of investment. | D68: bankacct_customer_pay | E68: PII | F68: Y | G68: - | H68: 8172756991 4240736619 0492842458 0602333338 0242881872 | I68: Nattaphat Buddharee | J68: Pichai Lertsupongkit | K68: 45372 | L68: Phatcharaporn L. | M68: - | N68: account information
A69: 68 | B69: Data Lake Load Date/Time | C69: A date and time on which the data was ingested into the Data Lake. Note: The format is represented as 'YYYY-MM-DD hh:mm:ss'. | D69: data_date | E69: Non-PII | F69: Y | G69: - | H69: 45452 | I69: Nattaphat Buddharee | J69: Pichai Lertsupongkit | K69: 45454 | L69: Tossawat P | M69: - | N69: center_cq_cash_balance
A70: 69 | B70: Account Number | C70: Account number refers to the account number of investment.The account can be for any products. (e.g. deposit, loan, investment etc.). | D70: account | E70: PII | F70: Y | G70: - | H70: 144xxx6 144xxx4 144xxx2 144xxx6 144xxx8 | I70: Nattaphat Buddharee | J70: Pichai Lertsupongkit | K70: 45454 | L70: Tossawat P | M70: - | N70: center_cq_cash_balance
A71: 70 | B71: Sub Account Number | C71: Sub Account number refers to the account number of investment.The account can be for any products. (e.g. deposit, loan, investment etc.). | D71: sub_account | E71: PII | F71: Y | G71: - | H71: 144xxx6 144xxx4 144xxx2 144xxx6 144xxx8 | I71: Nattaphat Buddharee | J71: Pichai Lertsupongkit | K71: 45454 | L71: Tossawat P | M71: - | N71: center_cq_cash_balance
A72: 71 | B72: Currency Code | C72: Currency Code comprises of a 3-digit code number assigned to each country's currency specified by the International Organization for Standardization (ISO). The three-digit numeric code is used to represent countries, dependent territories and special areas of geographical interest. | D72: currency | E72: Non-PII | F72: Y | G72: - | H72: VND MYR USD SGD CAD | I72: Nattaphat Buddharee | J72: Pichai Lertsupongkit | K72: 45454 | L72: Tossawat P | M72: - | N72: center_cq_cash_balance
A73: 72 | B73: B2B Code | C73: โบร์กเกอร์ Market Maker | D73: b2b_code | E73: Non-PII | F73: Y | G73: - | H73: GTN PSPL BFLD SAXO ECLR | I73: Nattaphat Buddharee | J73: Pichai Lertsupongkit | K73: 45454 | L73: Tossawat P | M73: - | N73: center_cq_cash_balance
A74: 73 | B74: Available Amount | C74: Line Available is the actual buying amount at that time. or the actual value of the remaining amount Which is update in real-time, that is, when an investor sends an order, this amount will be changed immediately, even if the order has not yet been matched. And if the order is canceled The money will be returned immediately. | D74: amt_available | E74: Non-PII | F74: N | G74: - | H74: 878.6 836.29 1789.71 57.99 84.74 | I74: Nattaphat Buddharee | J74: Pichai Lertsupongkit | K74: 45454 | L74: Tossawat P | M74: - | N74: center_cq_cash_balance
A75: 74 | B75: Balance Amount | C75: Cash Balance is the cash value that can be withdrawn at that time. They are generally not updated in real-time and are slow to change due to the settlement process. | D75: amt_balance | E75: Non-PII | F75: N | G75: - | H75: 878.6 836.29 1789.71 57.99 84.74 | I75: Nattaphat Buddharee | J75: Pichai Lertsupongkit | K75: 45454 | L75: Tossawat P | M75: - | N75: center_cq_cash_balance
A76: 75 | B76: Data Lake Create Date/Time | C76: The data date on which the data has been processed and create on the Data Lake. Note: The format is represented as 'YYYY-MM-DD hh:mm:ss'. | D76: create_datetime | E76: Non-PII | F76: N | G76: - | H76: 2024-06-10 17:32:01.160 2024-06-10 17:32:01.823 2024-06-10 17:32:00.910 2024-06-10 17:32:01.603 2024-06-10 17:32:01.367 | I76: Nattaphat Buddharee | J76: Pichai Lertsupongkit | K76: 45454 | L76: Tossawat P | M76: - | N76: center_cq_cash_balance
A77: 76 | B77: Data Create By | C77: Identification of the owner processed and create data to the Data Lake. | D77: create_by | E77: Non-PII | F77: N | G77: - | H77: dailyImpCQCashBalanceStep | I77: Nattaphat Buddharee | J77: Pichai Lertsupongkit | K77: 45454 | L77: Tossawat P | M77: - | N77: center_cq_cash_balance
A78: 77 | B78: As of date | C78: Displays the date the source data entered the archive. | D78: run_date | E78: Non-PII | F78: N | G78: - | H78: 45404 | I78: Nattaphat Buddharee | J78: Pichai Lertsupongkit | K78: 45503 | L78: Tossawat P | M78: - | N78: fund_portfolio
A79: 78 | B79: Customer Number | C79: Customer Identification Number, abbreviated to 'Customer ID', is the identifier of customers. The Customer ID can be Thai National ID, Passport, Alien ID, or Registration ID depending on type of customers (Refer to Customer Type Code). Note: 1. Thai nationals are able to use Thai National ID or Passport as a supporting document. In the event of Thai nationals using passport (e.g. investment) as a supporting document and to differentiate them from Foreign nationals, please refer to attribute 'Customer Nationality Code'. 2. The corporations/organizations (non-Individual) use 'registration of juristic person' or 'memorandum of association' as Business Registration ID, Store Registration ID, Other Registration ID, Swift ID, or Tax ID. 3. The Aliens use passport or Alien ID as a supporting document. Format of Alien ID length >= 2 and contain only Thai alphabet, Number, Dash, Slash, and Period. 13 Digits value, begin with 0, 6, 7, or 8 Format of Passport ID Contain only EN Capital, Number, and Dash, length >= 4 and first 2 characters are English capital which is nationality of customer. 4. Other Types of IDs may include Temporary Business ID (Corporations only), Staff ID, and Temporary Persons ID (Individuals only). | D79: customer_number | E79: PII | F79: Y | G79: - | H79: 3100400152332 3100200845342 1100400320123 3229800019912 1739900237988 | I79: Nattaphat Buddharee | J79: Pichai Lertsupongkit | K79: 45503 | L79: Tossawat P | M79: - | N79: fund_portfolio
A80: 79 | B80: Account Identifier | C80: Account number refers to the account number of Title loan account or revolving credit account. | D80: account_id | E80: PII | F80: Y | G80: - | H80: 81001760 81002253 81004393 81004606 81004724 | I80: Nattaphat Buddharee | J80: Pichai Lertsupongkit | K80: 45503 | L80: Tossawat P | M80: - | N80: fund_portfolio
A81: 80 | B81: Unitholder Identifier | C81: Unitholder ID will show information separated by the mutual fund company in which the investor has invested. You can view information on the website and application page. | D81: unit_holder_id | E81: PII | F81: Y | G81: - | H81: 023000000366 7640000670 7640005406 0370010000380 000003985290 | I81: Nattaphat Buddharee | J81: Pichai Lertsupongkit | K81: 45503 | L81: Tossawat P | M81: - | N81: fund_portfolio
A82: 81 | B82: Asset Management Companies Code | C82: Company list Asset Management, or AMC, is a company that invests in mutual funds on behalf of its clients. This capital is used to fund different investments across different asset classes Asset Class An asset class is a group of similar investment vehicles. Different classes or types of investment assets, such as fixed income investments, are grouped together with similar financial structures. They generally trade on the same financial markets and are subject to the same rules and regulations. Asset management companies are often referred to as money managers or money management companies as well | D82: amc_code | E82: Non-PII | F82: Y | G82: - | H82: ASSETFUND BCAP SCBAM TISCOASSET KSAM | I82: Nattaphat Buddharee | J82: Pichai Lertsupongkit | K82: 45503 | L82: Tossawat P | M82: - | N82: fund_portfolio
A83: 82 | B83: Fund Code | C83: All fund product codes under the company INVX manages, including products under other mutual fund companies. | D83: fund_code | E83: Non-PII | F83: Y | G83: - | H83: KFMTFI TMBGQGRMF SCBRM1-51 TMBAGLF ASPGIPLUS-R | I83: Nattaphat Buddharee | J83: Pichai Lertsupongkit | K83: 45503 | L83: Tossawat P | M83: - | N83: fund_portfolio
A84: 83 | B84: Available Unit Balance | C84: Number of investment units remaining of the customer | D84: available_unit_balance | E84: Non-PII | F84: Y | G84: - | H84: 1383.4779 20.3162 24792.093 1670.1308 7805.9442 | I84: Nattaphat Buddharee | J84: Pichai Lertsupongkit | K84: 45503 | L84: Tossawat P | M84: - | N84: fund_portfolio
A85: 84 | B85: Available Amount | C85: Fund value Calculated from the number of units remaining x Net Asset Value | D85: available_amount | E85: Non-PII | F85: N | G85: - | H85: 13025246.74 103491.48 48142.58 553131.76 0.24 | I85: Nattaphat Buddharee | J85: Pichai Lertsupongkit | K85: 45503 | L85: Tossawat P | M85: - | N85: fund_portfolio
A86: 85 | B86: Average Cost | C86: Average customer cost of remaining investment units Calculated using the FIFO principle from the total share value divided by the total number of shares | D86: average_cost | E86: Non-PII | F86: Y | G86: - | H86: 10.2361 12.8215 11.0039 10.8203 12.5052 | I86: Nattaphat Buddharee | J86: Pichai Lertsupongkit | K86: 45503 | L86: Tossawat P | M86: - | N86: fund_portfolio
A87: 86 | B87: NET Asset Value | C87: net assets or the total investment value and benefits received by the mutual fund Subtract from expenses and various liabilities per 1 investment unit | D87: nav | E87: Non-PII | F87: Y | G87: - | H87: 16.4332 12.7165 6.0962 6.0294 14.7642 | I87: Nattaphat Buddharee | J87: Pichai Lertsupongkit | K87: 45503 | L87: Tossawat P | M87: - | N87: fund_portfolio
A88: 87 | B88: NET Asset Value Date | C88: Date of calculation of net asset value | D88: nav_date | E88: Non-PII | F88: N | G88: - | H88: 2024-02-29 2024-03-27 2023-04-20 2024-03-31 2024-03-26 | I88: Nattaphat Buddharee | J88: Pichai Lertsupongkit | K88: 45503 | L88: Tossawat P | M88: - | N88: fund_portfolio
A89: 88 | B89: Unrealized Gain / Loss amount | C89: Profit/Loss that have not yet been realized Calculated from (Net Asset Value - Average Cost) x Available Unit | D89: unrealize_gl | E89: Non-PII | F89: N | G89: - | H89: 25.327679 -2020.866467 57344.046435 10.098284 48359.46598 | I89: Nattaphat Buddharee | J89: Pichai Lertsupongkit | K89: 45503 | L89: Tossawat P | M89: - | N89: fund_portfolio
A90: 89 | B90: Run Date | C90: Data update date | D90: run_date | E90: Non-PII | F90: N | G90: - | H90: 45404 | I90: Nattaphat Buddharee | J90: Pichai Lertsupongkit | K90: 45503 | L90: Tossawat P | M90: - | N90: fund_transactions
A91: 90 | B91: Transaction Identifier | C91: Mutual fund customer transaction number | D91: transaction_id | E91: PII | F91: Y | G91: - | H91: 1082404190000027 1082404190002551 1082404190011241 1082404200001911 1082404220005641 | I91: Nattaphat Buddharee | J91: Pichai Lertsupongkit | K91: 45503 | L91: Tossawat P | M91: - | N91: fund_transactions
A92: 91 | B92: FundConnext Reference Number | C92: Reference No. that the INVX system sends orders to FundConnext | D92: sa_order_ref_no | E92: PII | F92: N | G92: - | H92: 0801WA20240418170412-A12660735 EI-EA_c4eec6c05d5442b4872e2d50 EIUSR_e526ff3221cc45f18d8f6c07 0807MC20240419192754-B12666647 EIUSR_eb5c7c98100647a58db6f98b | I92: Nattaphat Buddharee | J92: Pichai Lertsupongkit | K92: 45503 | L92: Tossawat P | M92: - | N92: fund_transactions
A93: 92 | B93: Transaction Date | C93: Date the customer made the transaction | D93: transaction_date | E93: PII | F93: Y | G93: - | H93: 2024-02-20 2024-04-02 2024-04-14 2024-04-13 2024-04-12 | I93: Nattaphat Buddharee | J93: Pichai Lertsupongkit | K93: 45503 | L93: Tossawat P | M93: - | N93: fund_transactions
A94: 93 | B94: Transaction Time | C94: Shows the time of the customer's transaction. which corresponds to transaction_date | D94: transaction_time | E94: Non-PII | F94: Y | G94: - | H94: 00:07:15.0000000 12:13:05.0000000 00:29:47.0000000 13:32:29.0000000 23:24:29.0000000 | I94: Nattaphat Buddharee | J94: Pichai Lertsupongkit | K94: 45503 | L94: Tossawat P | M94: - | N94: fund_transactions
...

Sheet Scope & Condition by field
A1: Metadata Type | B1: Metric | C1: Field | D1: Condition By Field
A2: Metadata Column | B2: Completeness | C2: Column Name | D2: Can not be blank
A3: Metadata Column | B3: Completeness | C3: Data Set Name | D3: Can not be blank
A4: Metadata Column | B4: Completeness | C4: Data Zone (MDZ/GDZ) | D4: Can not be blank
A5: Metadata Column | B5: Completeness | C5: Format | D5: Can not be blank
A6: Metadata Column | B6: Completeness | C6: Nullable | D6: Can not be blank
A7: Metadata Column | B7: Completeness | C7: PII/ Non-PII | D7: Can not be blank
A8: Metadata Column | B8: Completeness | C8: Schema/Database Name | D8: Can not be blank
A9: Metadata Column | B9: Completeness | C9: System/ Data Subject Area Name | D9: Can not be blank
A10: Metadata Column | B10: Completeness | C10: Type | D10: Can not be blank
A11: Metadata Column | B11: Completeness | C11: Updated By | D11: Can not be blank
A12: Metadata Column | B12: Completeness | C12: Updated Date | D12: Can not be blank
... A55: Metadata Data Set | B55: Uniqueness | C55: Data Set Description | D55: Do not duplicate

Sheet Summary
A1: Metadata Type (Business or Technical) | B1: Metadata Sub-Type (Business/Data set/Column) | C1: Metric | D1: Field | E1: %of Metadata Quality by field | F1: Key | G1: Order
A2: Business Metadata | B2: Business Metadata | C2: Accuracy | D2: Business Attribute Name | E2: =AVERAGE('Cal_Business Metadata'!AD:AD) -> 1 | F2: Business MetadataAccuracyBusiness Attribute Name
A3: Business Metadata | B3: Business Metadata | C3: Accuracy | D3: Column Name | E3: =AVERAGE('Cal_Business Metadata'!AF:AF) -> 1 | F3: Business MetadataAccuracyColumn Name
A4: Business Metadata | B4: Business Metadata | C4: Accuracy | D4: Business Definition | E4: =AVERAGE('Cal_Business Metadata'!AE:AE) -> 1 | F4: Business MetadataAccuracyBusiness Definition
A5: Business Metadata | B5: Business Metadata | C5: Accuracy | D5: Data Owner | E5: =AVERAGE('Cal_Business Metadata'!AH:AH) -> 1 | F5: Business MetadataAccuracyData Owner
A6: Business Metadata | B6: Business Metadata | C6: Accuracy | D6: Business Data Steward | E6: =AVERAGE('Cal_Business Metadata'!AG:AG) -> 1 | F6: Business MetadataAccuracyBusiness Data Steward
A7: Business Metadata | B7: Business Metadata | C7: Accuracy | D7: Updated By | E7: =AVERAGE('Cal_Business Metadata'!AI:AI) -> 1 | F7: Business MetadataAccuracyUpdated By
A8: Business Metadata | B8: Business Metadata | C8: Completeness | D8: Business Attribute Name | E8: =AVERAGE('Cal_Business Metadata'!N:N) -> 1 | F8: Business MetadataCompletenessBusiness Attribute Name
A9: Business Metadata | B9: Business Metadata | C9: Completeness | D9: Business Definition | E9: =AVERAGE('Cal_Business Metadata'!O:O) -> 1 | F9: Business MetadataCompletenessBusiness Definition
A10: Business Metadata | B10: Business Metadata | C10: Completeness | D10: Column Name | E10: =AVERAGE('Cal_Business Metadata'!P:P) -> 1 | F10: Business MetadataCompletenessColumn Name
A11: Business Metadata | B11: Business Metadata | C11: Completeness | D11: PII/ Non-PII | E11: =AVERAGE('Cal_Business Metadata'!Q:Q) -> 1 | F11: Business MetadataCompletenessPII/ Non-PII
A12: Business Metadata | B12: Business Metadata | C12: Completeness | D12: Sample Data | E12: =AVERAGE('Cal_Business Metadata'!X:X) -> 1 | F12: Business MetadataCompletenessSample Data
A13: Business Metadata | B13: Business Metadata | C13: Completeness | D13: Business Data Steward | E13: =AVERAGE('Cal_Business Metadata'!Y:Y) -> 1 | F13: Business MetadataCompletenessBusiness Data Steward
A14: Business Metadata | B14: Business Metadata | C14: Completeness | D14: Data Owner | E14: =AVERAGE('Cal_Business Metadata'!Z:Z) -> 1 | F14: Business MetadataCompletenessData Owner
A15: Business Metadata | B15: Business Metadata | C15: Completeness | D15: Updated Date | E15: =AVERAGE('Cal_Business Metadata'!AA:AA) -> 1 | F15: Business MetadataCompletenessUpdated Date
A16: Business Metadata | B16: Business Metadata | C16: Completeness | D16: Updated By | E16: =AVERAGE('Cal_Business Metadata'!AB:AB) -> 1 | F16: Business MetadataCompletenessUpdated By
A17: Business Metadata | B17: Business Metadata | C17: Completeness | D17: List of Allowable Values | E17: =AVERAGE('Cal_Business Metadata'!W:W) -> 1 | F17: Business MetadataCompletenessList of Allowable Values
A18: Business Metadata | B18: Business Metadata | C18: Consistency | D18: Have column in Metadata Column | E18: =AVERAGE('Cal_Business Metadata'!AP8) -> 1 | F18: Business MetadataConsistencyHave column in Metadata Column
A19: Business Metadata | B19: Business Metadata | C19: Integrity | D19: PII/Non-PII | E19: =AVERAGE('Cal_Business Metadata'!AK:AK) -> 1 | F19: Business MetadataIntegrityPII/ Non-PII
A20: Business Metadata | B20: Business Metadata | C20: Uniqueness | D20: Business Attribute Name | E20: =AVERAGE('Cal_Business Metadata'!AM:AM) -> 1 | F20: Business MetadataUniquenessBusiness Attribute Name
A21: Business Metadata | B21: Business Metadata | C21: Uniqueness | D21: Business Definition | E21: =AVERAGE('Cal_Business Metadata'!AP:AP) -> 0.97368421 | F21: Business MetadataUniquenessBusiness Definition
A22: Technical Metadata | B22: Metadata Column | C22: Accuracy | D22: Column Name | E22: =AVERAGE('Cal_Technical - Column'!AG:AG) -> 1 | F22: Metadata ColumnAccuracyColumn Name
A23: Technical Metadata | B23: Metadata Column | C23: Accuracy | D23: Data Set Name | E23: =AVERAGE('Cal_Technical - Column'!AF:AF) -> 1 | F23: Metadata ColumnAccuracyData Set Name
A24: Technical Metadata | B24: Metadata Column | C24: Accuracy | D24: Schema/Database Name | E24: =AVERAGE('Cal_Technical - Column'!AE:AE) -> 1 | F24: Metadata ColumnAccuracySchema/Database Name
A25: Technical Metadata | B25: Metadata Column | C25: Accuracy | D25: System/Data Subject Area Name | E25: =AVERAGE('Cal_Technical - Column'!AD:AD) -> 1 | F25: Metadata ColumnAccuracySystem/ Data Subject Area Name
A26: Technical Metadata | B26: Metadata Column | C26: Accuracy | D26: Updated By | E26: =AVERAGE('Cal_Technical - Column'!AH:AH) -> 1 | F26: Metadata ColumnAccuracyUpdated By
A27: Technical Metadata | B27: Metadata Column | C27: Completeness | D27: Column Name | E27: =AVERAGE('Cal_Technical - Column'!Q:Q) -> 1 | F27: Metadata ColumnCompletenessColumn Name
A28: Technical Metadata | B28: Metadata Column | C28: Completeness | D28: Data Set Name | E28: =AVERAGE('Cal_Technical - Column'!P:P) -> 1 | F28: Metadata ColumnCompletenessData Set Name
A29: Technical Metadata | B29: Metadata Column | C29: Completeness | D29: Data Zone(MDZ/GDZ) | E29: =AVERAGE('Cal_Technical - Column'!R:R) -> 1 | F29: Metadata ColumnCompletenessData Zone (MDZ/GDZ)
A30: Technical Metadata | B30: Metadata Column | C30: Completeness | D30: Format | E30: =AVERAGE('Cal_Technical - Column'!U:U) -> 1 | F30: Metadata ColumnCompletenessFormat
A31: Technical Metadata | B31: Metadata Column | C31: Completeness | D31: Nullable | E31: =AVERAGE('Cal_Technical - Column'!V:V) -> 1 | F31: Metadata ColumnCompletenessNullable
A32: Technical Metadata | B32: Metadata Column | C32: Completeness | D32: PII/Non-PII | E32: =AVERAGE('Cal_Technical - Column'!S:S) -> 1 | F32: Metadata ColumnCompletenessPII/ Non-PII
A33: Technical Metadata | B33: Metadata Column | C33: Completeness | D33: Schema/Database Name | E33: =AVERAGE('Cal_Technical - Column'!O:O) -> 1 | F33: Metadata ColumnCompletenessSchema/Database Name
A34: Technical Metadata | B34: Metadata Column | C34: Completeness | D34: System/Data Subject Area Name | E34: =AVERAGE('Cal_Technical - Column'!N:N) -> 1 | F34: Metadata ColumnCompletenessSystem/ Data Subject Area Name
A35: Technical Metadata | B35: Metadata Column | C35: Completeness | D35: Type | E35: =AVERAGE('Cal_Technical - Column'!T:T) -> 1 | F35: Metadata ColumnCompletenessType
A36: Technical Metadata | B36: Metadata Column | C36: Completeness | D36: Updated By | E36: =AVERAGE('Cal_Technical - Column'!X:X) -> 1 | F36: Metadata ColumnCompletenessUpdated By
A37: Technical Metadata | B37: Metadata Column | C37: Completeness | D37: Updated Date | E37: =AVERAGE('Cal_Technical - Column'!W:W) -> 1 | F37: Metadata ColumnCompletenessUpdated Date
A38: Technical Metadata | B38: Metadata Column | C38: Consistency | D38: Have data set in Metadata Data Set | E38: =AVERAGE('Cal_Technical - Column'!Z:Z) -> 1 | F38: Metadata ColumnConsistencyHave data set in Metadata Data Set
A39: Technical Metadata | B39: Metadata Column | C39: Integrity | D39: Data Zone (MDZ/GDZ) | E39: =AVERAGE('Cal_Technical - Column'!AJ:AJ) -> 1 | F39: Metadata ColumnIntegrityData Zone (MDZ/GDZ)
A40: Technical Metadata | B40: Metadata Column | C40: Integrity | D40: PII/Non-PII | E40: =AVERAGE('Cal_Technical - Column'!AK:AK) -> 1 | F40: Metadata ColumnIntegrityPII/ Non-PII
...

Sheet Element
A1: Metadata Sub-Type (Business/Data set/Column) | B1: Total Elememt (by metadata sub-type)
A2: Business Metadata | B2: =COUNTA('Cal_Business Metadata'!B:B)-1 -> 154
A3: Metadata Column | B3: =COUNTA('Cal_Technical - Column'!D:D)-1 -> 154
A4: Metadata Data Set | B4: =COUNTA('Cal_Technical - Data Set'!A:A)-1 -> 5

Sheet Cal_Business Metadata
A1: No. | B1: Business Attribute Name | C1: Business Definition (EN) | D1: Column Name | E1: PII/Non-PII | F1: List of Allowable Values | G1: Sample Data | H1: Business Data Steward | I1: Data Owner | J1: Updated Date | K1: Updated By | L1: Subdomain | N1: Completeness Business Attribute Name | O1: Completeness Business Definition | P1: Completeness Column Name | Q1: Completeness PII/Non-PII | R1: Completeness Check_LOVisBlank [False] | S1: Completeness Check_LOVNameNot*Contains Flag [True] | T1: Completeness Check_LOVDefinitionNot*Contains "… can be contact" [True] | U1: Completeness Check_LOVDefinitionNot*Contains "… can be found" [True] | V1: Completeness Check_LOVDefinitionNot*Contains "list of allowable value" [True] | W1: Completeness List of Allowable Values | X1: Completeness Sample Data | Y1: Completeness Business Data Steward | Z1: Completeness Data Owner | AA1: Completeness Updated Date | AB1: Completeness Updated By | AD1: Accuracy Business Attribute Name | AE1: Accuracy Business Definition | AF1: Accuracy Column Name | AG1: Accuracy Business Data Steward | AH1: Accuracy Data Owner | AI1: Accuracy Updated By | AK1: Integrity PII/Non-PII | AM1: Uniqueness Business Attribute Name | AN1: Uniqueness Check_SubBusiness Definition | AO1: Uniqueness Business Definition | AP1: Uniqueness 1Business term: 1Column name | AR1: Consistency Have column in Metadata Column
A2: 1 | B2: Card Type List | C2: Type of card that customers use as evidence for account opening(ประเภทบัตรที่ลูกค้าใช้เป็นหลักฐานในการเปิดบัญชี) Sample list of allowable values include: CITIZEN_CARD = บัตรประชาชน PASSPORT = หนังสือเดินทาง ALIEN_CARD = บัตรต่างด้าว Company Tax ID = หมายเลขประจำตัวผู้เสียภาษีของบริษัท Company No = หมายเลขบริษัท Government_ID = หมายเลขรัฐวิสาหกิจ Please refer to link of allowable values for complete list of allowable values. | D2: card_type | E2: Non-PII | F2: Card_Type | G2: CITIZEN_CARD PASSPORT ALIEN_CARD Company Tax ID Company No | H2: Nattaphat Buddharee | I2: Pichai Lertsupongkit | J2: 45300 | K2: Tossawat P | L2: Customer Information | N2: =IF(ISBLANK(Calculate_Business_Metadata[[#This Row],[Business Attribute Name]])=TRUE, 0, 1) -> 1 | O2: =IF(ISBLANK(Calculate_Business_Metadata[[#This Row],[Business Definition (EN)]])=TRUE, 0, 1) -> 1 | P2: =IF(ISBLANK(Calculate_Business_Metadata[[#This Row],[Column Name]])=TRUE, 0, 1) -> 1 | Q2: =IF(ISBLANK(Calculate_Business_Metadata[[#This Row],[PII/Non-PII]])=TRUE, 0, 1) -> 1 | R2: =ISERROR(FIND("-", Calculate_Business_Metadata[[#This Row],[List of Allowable Values]])) -> TRUE | S2: =ISERROR(FIND("Flag",Calculate_Business_Metadata[[#This Row],[List of Allowable Values]], 1)) -> TRUE | T2: =ISERROR(FIND("In this case, the list of allowable values can be contact",Calculate_Business_Metadata[[#This Row],[List of Allowable Values]], 1)) -> TRUE | U2: =ISERROR(FIND("In this case, the list of allowable values can be found",Calculate_Business_Metadata[[#This Row],[List of Allowable Values]], 1)) -> TRUE | V2: =ISERROR(FIND("list of allowable values",Calculate_Business_Metadata[[#This Row],[List of Allowable Values]], 1)) -> TRUE | W2: =IF(OR(R2=TRUE,S2=FALSE, T2=FALSE,U2=FALSE)=TRUE, 1, IF(AND(R2=FALSE,S2=TRUE)=TRUE, 1, 0)) -> 1 | X2: =IF(ISBLANK(Calculate_Business_Metadata[[#This Row],[Sample Data]])=TRUE, 0, 1) -> 1 | Y2: =IF(ISBLANK(Calculate_Business_Metadata[[#This Row],[Business Data Steward]])=TRUE, 0, 1) -> 1 | Z2: =IF(ISBLANK(Calculate_Business_Metadata[[#This Row],[Data Owner]])=TRUE, 0, 1) -> 1 | AA2: =IF(ISBLANK(Calculate_Business_Metadata[[#This Row],[Updated Date]])=TRUE, 0, 1) -> 1 | AB2: =IF(ISBLANK(Calculate_Business_Metadata[[#This Row],[Updated By]])=TRUE, 0, 1) -> 1 | AD2: =IF(OR( ISERROR(FIND(" ",Calculate_Business_Metadata[[#This Row],[Business Attribute Name]], 1))=FALSE, ISERROR(FIND("_",Calculate_Business_Metadata[[#This Row],[Business Attribute Name]], 1))=FALSE)=TRUE, 0, 1) -> 1 | AE2: =IF(OR( ISERROR(FIND(" ",Calculate_Business_Metadata[[#This Row],[Business Definition (EN)]], 1))=FALSE, ISERROR(FIND("__",Calculate_Business_Metadata[[#This Row],[Business Definition (EN)]], 1))=FALSE)=TRUE, 0, 1) -> 1 | AF2: =IF(OR( ISERROR(FIND(" ",Calculate_Business_Metadata[[#This Row],[Column Name]], 1))=FALSE, ISERROR(FIND("__",Calculate_Business_Metadata[[#This Row],[Column Name]], 1))=FALSE)=TRUE, 0, 1) -> 1 | AG2: =IF(OR( ISERROR(FIND(" ",Calculate_Business_Metadata[[#This Row],[Business Data Steward]], 1))=FALSE, ISERROR(FIND("_",Calculate_Business_Metadata[[#This Row],[Business Data Steward]], 1))=FALSE)=TRUE, 0, 1) -> 1 | AH2: =IF(OR( ISERROR(FIND(" ",Calculate_Business_Metadata[[#This Row],[Data Owner]], 1))=FALSE, ISERROR(FIND("_",Calculate_Business_Metadata[[#This Row],[Data Owner]], 1))=FALSE)=TRUE, 0, 1) -> 1 | AI2: =IF(OR( ISERROR(FIND(" ",Calculate_Business_Metadata[[#This Row],[Updated By]], 1))=FALSE, ISERROR(FIND("_",Calculate_Business_Metadata[[#This Row],[Updated By]], 1))=FALSE)=TRUE, 0, 1) -> 1 | AK2: =IF(OR(ISERROR(FIND("PII",Calculate_Business_Metadata[[#This Row],[PII/Non-PII]], 1))=FALSE, ISERROR(FIND("PII",Calculate_Business_Metadata[[#This Row],[PII/Non-PII]], 1))=FALSE)=TRUE, 1, 0) -> 1 | AM2: =IF( COUNTIFS(B:B, Calculate_Business_Metadata[[#This Row],[Business Attribute Name]], D:D, Calculate_Business_Metadata[[#This Row],[Column Name]], L:L, Calculate_Business_Metadata[[#This Row],[Subdomain]]) > 1, 0, 1) -> 1 | AN2: =LEFT(Calculate_Business_Metadata[[#This Row],[Business Definition (EN)]], 150) -> Type of card that customers use as evidence for account opening(ประเภทบัตรที่ลูกค้าใช้เป็นหลักฐานในการเปิดบัญชี) Sample list of allowable values incl | AO2: =IF( COUNTIFS(AO:AO,AN2, B:B, Calculate_Business_Metadata[[#This Row],[Business Attribute Name]],L:L, Calculate_Business_Metadata[[#This Row],[Subdomain]]) <> 1, 0, 1) -> 0 | AP2: =IF(COUNTIFS(B:B, Calculate_Business_Metadata[[#This Row],[Business Attribute Name]], D:D, Calculate_Business_Metadata[[#This Row],[Column Name]], AN:AN, AN2) >1, 0, 1) -> 1 | AR2: =IF(COUNTIFS('Cal_Technical - Column'!D:D, Calculate_Business_Metadata[[#This Row],[Column Name]])> 0, 1, 0) -> 1
A3: 2 | B3: Passport Country Code | C3: The passport country code represents the name of the country from which the passport was issued (only in the case of PASSPORT). It is stored as a 2-digit or 3-digit abbreviation code ประเทศที่ออก passport ของลูกค้า (เฉพาะกรณี PASSPORT เท่านั้น) Sample list of allowable values include: IN = INDIA CN = CHINA GB = UNITED KINGDOM US = UNITED STATES JP = JAPAN Please refer to link of allowable values for complete list of allowable values. | D3: passport_country | E3: Non-PII | F3: Passport_Country_code | G3: IN CN GB US JP | H3: Nattaphat Buddharee | I3: Pichai Lertsupongkit | J3: 45300 | K3: Tossawat P | L3: Customer Information | N3: =IF(ISBLANK(Calculate_Business_Metadata[[#This Row],[Business Attribute Name]])=TRUE, 0, 1) -> 1 | O3: =IF(ISBLANK(Calculate_Business_Metadata[[#This Row],[Business Definition (EN)]])=TRUE, 0, 1) -> 1 | P3: =IF(ISBLANK(Calculate_Business_Metadata[[#This Row],[Column Name]])=TRUE, 0, 1) -> 1 | Q3: =IF(ISBLANK(Calculate_Business_Metadata[[#This Row],[PII/Non-PII]])=TRUE, 0, 1) -> 1 | R3: =ISERROR(FIND("-", Calculate_Business_Metadata[[#This Row],[List of Allowable Values]])) -> TRUE | S3: =ISERROR(FIND("Flag",Calculate_Business_Metadata[[#This Row],[List of Allowable Values]], 1)) -> TRUE | T3: =ISERROR(FIND("In this case, the list of allowable values can be contact",Calculate_Business_Metadata[[#This Row],[List of Allowable Values]], 1)) -> TRUE | U3: =ISERROR(FIND("In this case, the list of allowable values can be found",Calculate_Business_Metadata[[#This Row],[List of Allowable Values]], 1)) -> TRUE | V3: =ISERROR(FIND("list of allowable values",Calculate_Business_Metadata[[#This Row],[List of Allowable Values]], 1)) -> TRUE | W3: =IF(OR(R3=TRUE,S3=FALSE, T3=FALSE,U3=FALSE)=TRUE, 1, IF(AND(R3=FALSE,S3=TRUE)=TRUE, 1, 0)) -> 1 | X3: =IF(ISBLANK(Calculate_Business_Metadata[[#This Row],[Sample Data]])=TRUE, 0, 1) -> 1 | Y3: =IF(ISBLANK(Calculate_Business_Metadata[[#This Row],[Business Data Steward]])=TRUE, 0, 1) -> 1 | Z3: =IF(ISBLANK(Calculate_Business_Metadata[[#This Row],[Data Owner]])=TRUE, 0, 1) -> 1 | AA3: =IF(ISBLANK(Calculate_Business_Metadata[[#This Row],[Updated Date]])=TRUE, 0, 1) -> 1 | AB3: =IF(ISBLANK(Calculate_Business_Metadata[[#This Row],[Updated By]])=TRUE, 0, 1) -> 1 | AD3: =IF(OR( ISERROR(FIND(" ",Calculate_Business_Metadata[[#This Row],[Business Attribute Name]], 1))=FALSE, ISERROR(FIND("_",Calculate_Business_Metadata[[#This Row],[Business Attribute Name]], 1))=FALSE)=TRUE, 0, 1) -> 1 | AE3: =IF(OR( ISERROR(FIND(" ",Calculate_Business_Metadata[[#This Row],[Business Definition (EN)]], 1))=FALSE, ISERROR(FIND("__",Calculate_Business_Metadata[[#This Row],[Business Definition (EN)]], 1))=FALSE)=TRUE, 0, 1) -> 1 | AF3: =IF(OR( ISERROR(FIND(" ",Calculate_Business_Metadata[[#This Row],[Column Name]], 1))=FALSE, ISERROR(FIND("__",Calculate_Business_Metadata[[#This Row],[Column Name]], 1))=FALSE)=TRUE, 0, 1) -> 1 | AG3: =IF(OR( ISERROR(FIND(" ",Calculate_Business_Metadata[[#This Row],[Business Data Steward]], 1))=FALSE, ISERROR(FIND("_",Calculate_Business_Metadata[[#This Row],[Business Data Steward]], 1))=FALSE)=TRUE, 0, 1) -> 1 | AH3: =IF(OR( ISERROR(FIND(" ",Calculate_Business_Metadata[[#This Row],[Data Owner]], 1))=FALSE, ISERROR(FIND("_",Calculate_Business_Metadata[[#This Row],[Data Owner]], 1))=FALSE)=TRUE, 0, 1) -> 1 | AI3: =IF(OR( ISERROR(FIND(" ",Calculate_Business_Metadata[[#This Row],[Updated By]], 1))=FALSE, ISERROR(FIND("_",Calculate_Business_Metadata[[#This Row],[Updated By]], 1))=FALSE)=TRUE, 0, 1) -> 1 | AK3: =IF(OR(ISERROR(FIND("PII",Calculate_Business_Metadata[[#This Row],[PII/Non-PII]], 1))=FALSE, ISERROR(FIND("PII",Calculate_Business_Metadata[[#This Row],[PII/Non-PII]], 1))=FALSE)=TRUE, 1, 0) -> 1 | AM3: =IF( COUNTIFS(B:B, Calculate_Business_Metadata[[#This Row],[Business Attribute Name]], D:D, Calculate_Business_Metadata[[#This Row],[Column Name]], L:L, Calculate_Business_Metadata[[#This Row],[Subdomain]]) > 1, 0, 1) -> 1 | AN3: =LEFT(Calculate_Business_Metadata[[#This Row],[Business Definition (EN)]], 150) -> The passport country code represents the name of the country from which the passport was issued (only in the case of PASSPORT). It is stored as a 2-di | AO3: =IF( COUNTIFS(AO:AO,AN3, B:B, Calculate_Business_Metadata[[#This Row],[Business Attribute Name]],L:L, Calculate_Business_Metadata[[#This Row],[Subdomain]]) <> 1, 0, 1) -> 0 | AP3: =IF(COUNTIFS(B:B, Calculate_Business_Metadata[[#This Row],[Business Attribute Name]], D:D, Calculate_Business_Metadata[[#This Row],[Column Name]], AN:AN, AN3) >1, 0, 1) -> 1 | AR3: =IF(COUNTIFS('Cal_Technical - Column'!D:D, Calculate_Business_Metadata[[#This Row],[Column Name]])> 0, 1, 0) -> 1
A4: 3 | B4: Card Number | C4: Identification Number from the card the customer uses to open the account It can be a Thai ID card, passport No, or Alien identification card. This depends on the type of customer. Identification Number จากบัตรที่ลูกค้าใช้เปิดบัญชี | D4: card_number | E4: PII | F4: - | G4: 351274171 TR4395794 Z2666801 1100200285146 1100200459250 | H4: Nattaphat Buddharee | I4: Pichai Lertsupongkit | J4: 45264 | K4: Tossawat P | L4: Customer Information | N4: =IF(ISBLANK(Calculate_Business_Metadata[[#This Row],[Business Attribute Name]])=TRUE, 0, 1) -> 1 | O4: =IF(ISBLANK(Calculate_Business_Metadata[[#This Row],[Business Definition (EN)]])=TRUE, 0, 1) -> 1 | P4: =IF(ISBLANK(Calculate_Business_Metadata[[#This Row],[Column Name]])=TRUE, 0, 1) -> 1 | Q4: =IF(ISBLANK(Calculate_Business_Metadata[[#This Row],[PII/Non-PII]])=TRUE, 0, 1) -> 1 | R4: =ISERROR(FIND("-", Calculate_Business_Metadata[[#This Row],[List of Allowable Values]])) -> FALSE | S4: =ISERROR(FIND("Flag",Calculate_Business_Metadata[[#This Row],[List of Allowable Values]], 1)) -> TRUE | T4: =ISERROR(FIND("In this case, the list of allowable values can be contact",Calculate_Business_Metadata[[#This Row],[List of Allowable Values]], 1)) -> TRUE | U4: =ISERROR(FIND("In this case, the list of allowable values can be found",Calculate_Business_Metadata[[#This Row],[List of Allowable Values]], 1)) -> TRUE | V4: =ISERROR(FIND("list of allowable values",Calculate_Business_Metadata[[#This Row],[List of Allowable Values]], 1)) -> TRUE | W4: =IF(OR(R4=TRUE,S4=FALSE, T4=FALSE,U4=FALSE)=TRUE, 1, IF(AND(R4=FALSE,S4=TRUE)=TRUE, 1, 0)) -> 1 | X4: =IF(ISBLANK(Calculate_Business_Metadata[[#This Row],[Sample Data]])=TRUE, 0, 1) -> 1 | Y4: =IF(ISBLANK(Calculate_Business_Metadata[[#This Row],[Business Data Steward]])=TRUE, 0, 1) -> 1 | Z4: =IF(ISBLANK(Calculate_Business_Metadata[[#This Row],[Data Owner]])=TRUE, 0, 1) -> 1 | AA4: =IF(ISBLANK(Calculate_Business_Metadata[[#This Row],[Updated Date]])=TRUE, 0, 1) -> 1 | AB4: =IF(ISBLANK(Calculate_Business_Metadata[[#This Row],[Updated By]])=TRUE, 0, 1) -> 1 | AD4: =IF(OR( ISERROR(FIND(" ",Calculate_Business_Metadata[[#This Row],[Business Attribute Name]], 1))=FALSE, ISERROR(FIND("_",Calculate_Business_Metadata[[#This Row],[Business Attribute Name]], 1))=FALSE)=TRUE, 0, 1) -> 1 | AE4: =IF(OR( ISERROR(FIND(" ",Calculate_Business_Metadata[[#This Row],[Business Definition (EN)]], 1))=FALSE, ISERROR(FIND("__",Calculate_Business_Metadata[[#This Row],[Business Definition (EN)]], 1))=FALSE)=TRUE, 0, 1) -> 1 | AF4: =IF(OR( ISERROR(FIND(" ",Calculate_Business_Metadata[[#This Row],[Column Name]], 1))=FALSE, ISERROR(FIND("__",Calculate_Business_Metadata[[#This Row],[Column Name]], 1))=FALSE)=TRUE, 0, 1) -> 1 | AG4: =IF(OR( ISERROR(FIND(" ",Calculate_Business_Metadata[[#This Row],[Business Data Steward]], 1))=FALSE, ISERROR(FIND("_",Calculate_Business_Metadata[[#This Row],[Business Data Steward]], 1))=FALSE)=TRUE, 0, 1) -> 1 | AH4: =IF(OR( ISERROR(FIND(" ",Calculate_Business_Metadata[[#This Row],[Data Owner]], 1))=FALSE, ISERROR(FIND("_",Calculate_Business_Metadata[[#This Row],[Data Owner]], 1))=FALSE)=TRUE, 0, 1) -> 1 | AI4: =IF(OR( ISERROR(FIND(" ",Calculate_Business_Metadata[[#This Row],[Updated By]], 1))=FALSE, ISERROR(FIND("_",Calculate_Business_Metadata[[#This Row],[Updated By]], 1))=FALSE)=TRUE, 0, 1) -> 1 | AK4: =IF(OR(ISERROR(FIND("PII",Calculate_Business_Metadata[[#This Row],[PII/Non-PII]], 1))=FALSE, ISERROR(FIND("PII",Calculate_Business_Metadata[[#This Row],[PII/Non-PII]], 1))=FALSE)=TRUE, 1, 0) -> 1 | AM4: =IF( COUNTIFS(B:B, Calculate_Business_Metadata[[#This Row],[Business Attribute Name]], D:D, Calculate_Business_Metadata[[#This Row],[Column Name]], L:L, Calculate_Business_Metadata[[#This Row],[Subdomain]]) > 1, 0, 1) -> 1 | AN4: =LEFT(Calculate_Business_Metadata[[#This Row],[Business Definition (EN)]], 150) -> Identification Number from the card the customer uses to open the account It can be a Thai ID card, passport No, or Alien identification card. This de | AO4: =IF( COUNTIFS(AO:AO,AN4, B:B, Calculate_Business_Metadata[[#This Row],[Business Attribute Name]],L:L, Calculate_Business_Metadata[[#This Row],[Subdomain]]) <> 1, 0, 1) -> 0 | AP4: =IF(COUNTIFS(B:B, Calculate_Business_Metadata[[#This Row],[Business Attribute Name]], D:D, Calculate_Business_Metadata[[#This Row],[Column Name]], AN:AN, AN4) >1, 0, 1) -> 1 | AR4: =IF(COUNTIFS('Cal_Technical - Column'!D:D, Calculate_Business_Metadata[[#This Row],[Column Name]])> 0, 1, 0) -> 1
A5: 4 | B5: Card expiry Date | C5: Card expiration date means the date printed on the identification card used by the customer as evidence for opening an account. which indicates the expiration of the card's lifespan This date is set by the card issuing authority. The format should be ""YYYY-MM-DD" record: - If the customer does not have an expiration date on the card, the value will be 9999-12-31. วันหมดอายุของบัตรที่ลูกค้าใช้เป็นหลักฐานในการเปิดบัญชี | D5: card_expiry_date | E5: Non-PII | F5: - | G5: 9999-12-31 2099-12-31 1970-01-01 2023-12-31 2026-12-31 | H5: Nattaphat Buddharee | I5: Pichai Lertsupongkit | J5: 45264 | K5: Tossawat P | L5: Customer Information | N5: =IF(ISBLANK(Calculate_Business_Metadata[[#This Row],[Business Attribute Name]])=TRUE, 0, 1) -> 1 | O5: =IF(ISBLANK(Calculate_Business_Metadata[[#This Row],[Business Definition (EN)]])=TRUE, 0, 1) -> 1 | P5: =IF(ISBLANK(Calculate_Business_Metadata[[#This Row],[Column Name]])=TRUE, 0, 1) -> 1 | Q5: =IF(ISBLANK(Calculate_Business_Metadata[[#This Row],[PII/Non-PII]])=TRUE, 0, 1) -> 1 | R5: =ISERROR(FIND("-", Calculate_Business_Metadata[[#This Row],[List of Allowable Values]])) -> FALSE | S5: =ISERROR(FIND("Flag",Calculate_Business_Metadata[[#This Row],[List of Allowable Values]], 1)) -> TRUE | T5: =ISERROR(FIND("In this case, the list of allowable values can be contact",Calculate_Business_Metadata[[#This Row],[List of Allowable Values]], 1)) -> TRUE | U5: =ISERROR(FIND("In this case, the list of allowable values can be found",Calculate_Business_Metadata[[#This Row],[List of Allowable Values]], 1)) -> TRUE | V5: =ISERROR(FIND("list of allowable values",Calculate_Business_Metadata[[#This Row],[List of Allowable Values]], 1)) -> TRUE | W5: =IF(OR(R5=TRUE,S5=FALSE, T5=FALSE,U5=FALSE)=TRUE, 1, IF(AND(R5=FALSE,S5=TRUE)=TRUE, 1, 0)) -> 1 | X5: =IF(ISBLANK(Calculate_Business_Metadata[[#This Row],[Sample Data]])=TRUE, 0, 1) -> 1 | Y5: =IF(ISBLANK(Calculate_Business_Metadata[[#This Row],[Business Data Steward]])=TRUE, 0, 1) -> 1 | Z5: =IF(ISBLANK(Calculate_Business_Metadata[[#This Row],[Data Owner]])=TRUE, 0, 1) -> 1 | AA5: =IF(ISBLANK(Calculate_Business_Metadata[[#This Row],[Updated Date]])=TRUE, 0, 1) -> 1 | AB5: =IF(ISBLANK(Calculate_Business_Metadata[[#This Row],[Updated By]])=TRUE, 0, 1) -> 1 | AD5: =IF(OR( ISERROR(FIND(" ",Calculate_Business_Metadata[[#This Row],[Business Attribute Name]], 1))=FALSE, ISERROR(FIND("_",Calculate_Business_Metadata[[#This Row],[Business Attribute Name]], 1))=FALSE)=TRUE, 0, 1) -> 1 | AE5: =IF(OR( ISERROR(FIND(" ",Calculate_Business_Metadata[[#This Row],[Business Definition (EN)]], 1))=FALSE, ISERROR(FIND("__",Calculate_Business_Metadata[[#This Row],[Business Definition (EN)]], 1))=FALSE)=TRUE, 0, 1) -> 1 | AF5: =IF(OR( ISERROR(FIND(" ",Calculate_Business_Metadata[[#This Row],[Column Name]], 1))=FALSE, ISERROR(FIND("__",Calculate_Business_Metadata[[#This Row],[Column Name]], 1))=FALSE)=TRUE, 0, 1) -> 1 | AG5: =IF(OR( ISERROR(FIND(" ",Calculate_Business_Metadata[[#This Row],[Business Data Steward]], 1))=FALSE, ISERROR(FIND("_",Calculate_Business_Metadata[[#This Row],[Business Data Steward]], 1))=FALSE)=TRUE, 0, 1) -> 1 | AH5: =IF(OR( ISERROR(FIND(" ",Calculate_Business_Metadata[[#This Row],[Data Owner]], 1))=FALSE, ISERROR(FIND("_",Calculate_Business_Metadata[[#This Row],[Data Owner]], 1))=FALSE)=TRUE, 0, 1) -> 1 | AI5: =IF(OR( ISERROR(FIND(" ",Calculate_Business_Metadata[[#This Row],[Updated By]], 1))=FALSE, ISERROR(FIND("_",Calculate_Business_Metadata[[#This Row],[Updated By]], 1))=FALSE)=TRUE, 0, 1) -> 1 | AK5: =IF(OR(ISERROR(FIND("PII",Calculate_Business_Metadata[[#This Row],[PII/Non-PII]], 1))=FALSE, ISERROR(FIND("PII",Calculate_Business_Metadata[[#This Row],[PII/Non-PII]], 1))=FALSE)=TRUE, 1, 0) -> 1 | AM5: =IF( COUNTIFS(B:B, Calculate_Business_Metadata[[#This Row],[Business Attribute Name]], D:D, Calculate_Business_Metadata[[#This Row],[Column Name]], L:L, Calculate_Business_Metadata[[#This Row],[Subdomain]]) > 1, 0, 1) -> 1 | AN5: =LEFT(Calculate_Business_Metadata[[#This Row],[Business Definition (EN)]], 150) -> Card expiration date means the date printed on the identification card used by the customer as evidence for opening an account. which indicates the ex | AO5: =IF( COUNTIFS(AO:AO,AN5, B:B, Calculate_Business_Metadata[[#This Row],[Business Attribute Name]],L:L, Calculate_Business_Metadata[[#This Row],[Subdomain]]) <> 1, 0, 1) -> 0 | AP5: =IF(COUNTIFS(B:B, Calculate_Business_Metadata[[#This Row],[Business Attribute Name]], D:D, Calculate_Business_Metadata[[#This Row],[Column Name]], AN:AN, AN5) >1, 0, 1) -> 1 | AR5: =IF(COUNTIFS('Cal_Technical - Column'!D:D, Calculate_Business_Metadata[[#This Row],[Column Name]])> 0, 1, 0) -> 1
A6: 5 | B6: Gender Code | C6: Gender Code represents the code used to identify the gender of the customer. Current list of allowable values includes: M = Male F = Female O = Other | D6: gender | E6: Non-PII | F6: - | G6: M F O | H6: Nattaphat Buddharee | I6: Pichai Lertsupongkit | J6: 45300 | K6: Tossawat P | L6: Customer Information | N6: =IF(ISBLANK(Calculate_Business_Metadata[[#This Row],[Business Attribute Name]])=TRUE, 0, 1) -> 1 | O6: =IF(ISBLANK(Calculate_Business_Metadata[[#This Row],[Business Definition (EN)]])=TRUE, 0, 1) -> 1 | P6: =IF(ISBLANK(Calculate_Business_Metadata[[#This Row],[Column Name]])=TRUE, 0, 1) -> 1 | Q6: =IF(ISBLANK(Calculate_Business_Metadata[[#This Row],[PII/Non-PII]])=TRUE, 0, 1) -> 1 | R6: =ISERROR(FIND("-", Calculate_Business_Metadata[[#This Row],[List of Allowable Values]])) -> FALSE | S6: =ISERROR(FIND("Flag",Calculate_Business_Metadata[[#This Row],[List of Allowable Values]], 1)) -> TRUE | T6: =ISERROR(FIND("In this case, the list of allowable values can be contact",Calculate_Business_Metadata[[#This Row],[List of Allowable Values]], 1)) -> TRUE | U6: =ISERROR(FIND("In this case, the list of allowable values can be found",Calculate_Business_Metadata[[#This Row],[List of Allowable Values]], 1)) -> TRUE | V6: =ISERROR(FIND("list of allowable values",Calculate_Business_Metadata[[#This Row],[List of Allowable Values]], 1)) -> TRUE | W6: =IF(OR(R6=TRUE,S6=FALSE, T6=FALSE,U6=FALSE)=TRUE, 1, IF(AND(R6=FALSE,S6=TRUE)=TRUE, 1, 0)) -> 1 | X6: =IF(ISBLANK(Calculate_Business_Metadata[[#This Row],[Sample Data]])=TRUE, 0, 1) -> 1 | Y6: =IF(ISBLANK(Calculate_Business_Metadata[[#This Row],[Business Data Steward]])=TRUE, 0, 1) -> 1 | Z6: =IF(ISBLANK(Calculate_Business_Metadata[[#This Row],[Data Owner]])=TRUE, 0, 1) -> 1 | AA6: =IF(ISBLANK(Calculate_Business_Metadata[[#This Row],[Updated Date]])=TRUE, 0, 1) -> 1 | AB6: =IF(ISBLANK(Calculate_Business_Metadata[[#This Row],[Updated By]])=TRUE, 0, 1) -> 1 | AD6: =IF(OR( ISERROR(FIND(" ",Calculate_Business_Metadata[[#This Row],[Business Attribute Name]], 1))=FALSE, ISERROR(FIND("_",Calculate_Business_Metadata[[#This Row],[Business Attribute Name]], 1))=FALSE)=TRUE, 0, 1) -> 1 | AE6: =IF(OR( ISERROR(FIND(" ",Calculate_Business_Metadata[[#This Row],[Business Definition (EN)]], 1))=FALSE, ISERROR(FIND("__",Calculate_Business_Metadata[[#This Row],[Business Definition (EN)]], 1))=FALSE)=TRUE, 0, 1) -> 1 | AF6: =IF(OR( ISERROR(FIND(" ",Calculate_Business_Metadata[[#This Row],[Column Name]], 1))=FALSE, ISERROR(FIND("__",Calculate_Business_Metadata[[#This Row],[Column Name]], 1))=FALSE)=TRUE, 0, 1) -> 1 | AG6: =IF(OR( ISERROR(FIND(" ",Calculate_Business_Metadata[[#This Row],[Business Data Steward]], 1))=FALSE, ISERROR(FIND("_",Calculate_Business_Metadata[[#This Row],[Business Data Steward]], 1))=FALSE)=TRUE, 0, 1) -> 1 | AH6: =IF(OR( ISERROR(FIND(" ",Calculate_Business_Metadata[[#This Row],[Data Owner]], 1))=FALSE, ISERROR(FIND("_",Calculate_Business_Metadata[[#This Row],[Data Owner]], 1))=FALSE)=TRUE, 0, 1) -> 1 | AI6: =IF(OR( ISERROR(FIND(" ",Calculate_Business_Metadata[[#This Row],[Updated By]], 1))=FALSE, ISERROR(FIND("_",Calculate_Business_Metadata[[#This Row],[Updated By]], 1))=FALSE)=TRUE, 0, 1) -> 1 | AK6: =IF(OR(ISERROR(FIND("PII",Calculate_Business_Metadata[[#This Row],[PII/Non-PII]], 1))=FALSE, ISERROR(FIND("PII",Calculate_Business_Metadata[[#This Row],[PII/Non-PII]], 1))=FALSE)=TRUE, 1, 0) -> 1 | AM6: =IF( COUNTIFS(B:B, Calculate_Business_Metadata[[#This Row],[Business Attribute Name]], D:D, Calculate_Business_Metadata[[#This Row],[Column Name]], L:L, Calculate_Business_Metadata[[#This Row],[Subdomain]]) > 1, 0, 1) -> 1 | AN6: =LEFT(Calculate_Business_Metadata[[#This Row],[Business Definition (EN)]], 150) -> Gender Code represents the code used to identify the gender of the customer. Current list of allowable values includes: M = Male F = Female O = Othe | AO6: =IF( COUNTIFS(AO:AO,AN6, B:B, Calculate_Business_Metadata[[#This Row],[Business Attribute Name]],L:L, Calculate_Business_Metadata[[#This Row],[Subdomain]]) <> 1, 0, 1) -> 0 | AP6: =IF(COUNTIFS(B:B, Calculate_Business_Metadata[[#This Row],[Business Attribute Name]], D:D, Calculate_Business_Metadata[[#This Row],[Column Name]], AN:AN, AN6) >1, 0, 1) -> 1 | AR6: =IF(COUNTIFS('Cal_Technical - Column'!D:D, Calculate_Business_Metadata[[#This Row],[Column Name]])> 0, 1, 0) -> 1
